Workbook

Sheet Summary
A1: Three-Agent Monthly Cost Analysis | B1: Three-Agent Monthly Cost Analysis | C1: Three-Agent Monthly Cost Analysis | D1: Three-Agent Monthly Cost Analysis | E1: Three-Agent Monthly Cost Analysis | F1: Three-Agent Monthly Cost Analysis | G1: Three-Agent Monthly Cost Analysis | H1: Three-Agent Monthly Cost Analysis | I1: Three-Agent Monthly Cost Analysis
A2: Average case based on the inspected download, PageIndex, and answering agent code. Model/API costs and infrastructure are deliberately separated. | B2: Average case based on the inspected download, PageIndex, and answering agent code. Model/API costs and infrastructure are deliberately separated. | C2: Average case based on the inspected download, PageIndex, and answering agent code. Model/API costs and infrastructure are deliberately separated. | D2: Average case based on the inspected download, PageIndex, and answering agent code. Model/API costs and infrastructure are deliberately separated. | E2: Average case based on the inspected download, PageIndex, and answering agent code. Model/API costs and infrastructure are deliberately separated. | F2: Average case based on the inspected download, PageIndex, and answering agent code. Model/API costs and infrastructure are deliberately separated. | G2: Average case based on the inspected download, PageIndex, and answering agent code. Model/API costs and infrastructure are deliberately separated. | H2: Average case based on the inspected download, PageIndex, and answering agent code. Model/API costs and infrastructure are deliberately separated. | I2: Average case based on the inspected download, PageIndex, and answering agent code. Model/API costs and infrastructure are deliberately separated.
A4: Current model cost | B4: Current model cost | C4: Infrastructure cost | D4: Infrastructure cost | E4: All-in current | F4: All-in current
A5: ='Model Cost'!$L$22 -> 374.68873 | C5: ='Infra Cost'!$H$57 -> 9.5808814 | E5: =A5+C5 -> 384.26961
A8: Current cost / company | C8: Current cost / report | E8: Answering cost / question | G8: Model share of total
A9: =$E$5/Assumptions!$B$8 -> 19.21348 | C9: =($B$15+$C$15+$B$16+$C$16)/Assumptions!$B$10 -> 0.81327888 | E9: =($B$17+$C$17)/Assumptions!$B$12 -> 0.18730497 | G9: =$A$5/$E$5 -> 0.97506729
A10: Pricing basis | B10: USD; gross rates; free tiers excluded | C10: As-of | D10: 46231 | E10: Region | F10: us-east-1 / Vertex global | G10: Model status | H10: =Checks!$B$2 -> FAIL
A13: Monthly cost by agent | B13: Monthly cost by agent | C13: Monthly cost by agent | D13: Monthly cost by agent | E13: Monthly cost by agent | F13: Monthly cost by agent
A14: Agent | B14: Model — current | C14: Infrastructure | D14: All-in — current | E14: Model — post-promo | F14: All-in — post-promo
A15: Download Agent | B15: =SUMIF('Model Cost'!$A$14:$A$21,A15,'Model Cost'!$L$14:$L$21) -> 17.688728 | C15: =SUMIF('Infra Cost'!$A$30:$A$56,A15,'Infra Cost'!$H$30:$H$56) -> 3.6006405 | D15: =B15+C15 -> 21.289368 | E15: =SUMIF('Model Cost'!$A$14:$A$21,A15,'Model Cost'!$M$14:$M$21) -> 25.548728 | F15: =E15+C15 -> 29.149368
A16: PageIndex Agent | B16: =SUMIF('Model Cost'!$A$14:$A$21,A16,'Model Cost'!$L$14:$L$21) -> 171 | C16: =SUMIF('Infra Cost'!$A$30:$A$56,A16,'Infra Cost'!$H$30:$H$56) -> 2.8975625 | D16: =B16+C16 -> 173.89756 | E16: =SUMIF('Model Cost'!$A$14:$A$21,A16,'Model Cost'!$M$14:$M$21) -> 171 | F16: =E16+C16 -> 173.89756
A17: Answering Agent | B17: =SUMIF('Model Cost'!$A$14:$A$21,A17,'Model Cost'!$L$14:$L$21) -> 186 | C17: =SUMIF('Infra Cost'!$A$30:$A$56,A17,'Infra Cost'!$H$30:$H$56) -> 1.304974 | D17: =B17+C17 -> 187.30497 | E17: =SUMIF('Model Cost'!$A$14:$A$21,A17,'Model Cost'!$M$14:$M$21) -> 279 | F17: =E17+C17 -> 280.30497
A18: Shared | B18: =SUMIF('Model Cost'!$A$14:$A$21,A18,'Model Cost'!$L$14:$L$21) -> 0 | C18: =SUMIF('Infra Cost'!$A$30:$A$56,A18,'Infra Cost'!$H$30:$H$56) -> 1.7777044 | D18: =B18+C18 -> 1.7777044 | E18: =SUMIF('Model Cost'!$A$14:$A$21,A18,'Model Cost'!$M$14:$M$21) -> 0 | F18: =E18+C18 -> 1.7777044
A21: Current model cost by model | B21: Current model cost by model | C21: Current model cost by model
A22: Model / service | B22: Current monthly | C22: Post-promo monthly
A23: Claude Sonnet 5 | B23: =SUMIF('Model Cost'!$C$14:$C$21,A23,'Model Cost'!$L$14:$L$21) -> 201.72 | C23: =SUMIF('Model Cost'!$C$14:$C$21,A23,'Model Cost'!$M$14:$M$21) -> 302.58
A24: Claude Sonnet 4.5 | B24: =SUMIF('Model Cost'!$C$14:$C$21,A24,'Model Cost'!$L$14:$L$21) -> 171 | C24: =SUMIF('Model Cost'!$C$14:$C$21,A24,'Model Cost'!$M$14:$M$21) -> 171
A25: Gemini 2.5 Flash (thinking) | B25: =SUMIF('Model Cost'!$C$14:$C$21,A25,'Model Cost'!$L$14:$L$21) -> 1.9631 | C25: =SUMIF('Model Cost'!$C$14:$C$21,A25,'Model Cost'!$M$14:$M$21) -> 1.9631
A26: Amazon Nova 2 Lite | B26: =SUMIF('Model Cost'!$C$14:$C$21,A26,'Model Cost'!$L$14:$L$21) -> 0.005628 | C26: =SUMIF('Model Cost'!$C$14:$C$21,A26,'Model Cost'!$M$14:$M$21) -> 0.005628
A27: Vertex grounding | B27: =SUMIF('Model Cost'!$C$14:$C$21,A27,'Model Cost'!$L$14:$L$21) -> 0 | C27: =SUMIF('Model Cost'!$C$14:$C$21,A27,'Model Cost'!$M$14:$M$21) -> 0

Sheet Assumptions
A1: Agent Cost Analysis — Editable Assumptions | B1: Agent Cost Analysis — Editable Assumptions | C1: Agent Cost Analysis — Editable Assumptions | D1: Agent Cost Analysis — Editable Assumptions | E1: Agent Cost Analysis — Editable Assumptions | F1: Agent Cost Analysis — Editable Assumptions | G1: Agent Cost Analysis — Editable Assumptions | H1: Agent Cost Analysis — Editable Assumptions | I1: Agent Cost Analysis — Editable Assumptions | J1: Agent Cost Analysis — Editable Assumptions | K1: Agent Cost Analysis — Editable Assumptions
A2: Blue-font values are user-editable. Formula cells are black; cross-sheet links are green. USD, gross published rates, no free-tier credits. | B2: Blue-font values are user-editable. Formula cells are black; cross-sheet links are green. USD, gross published rates, no free-tier credits. | C2: Blue-font values are user-editable. Formula cells are black; cross-sheet links are green. USD, gross published rates, no free-tier credits. | D2: Blue-font values are user-editable. Formula cells are black; cross-sheet links are green. USD, gross published rates, no free-tier credits. | E2: Blue-font values are user-editable. Formula cells are black; cross-sheet links are green. USD, gross published rates, no free-tier credits. | F2: Blue-font values are user-editable. Formula cells are black; cross-sheet links are green. USD, gross published rates, no free-tier credits. | G2: Blue-font values are user-editable. Formula cells are black; cross-sheet links are green. USD, gross published rates, no free-tier credits. | H2: Blue-font values are user-editable. Formula cells are black; cross-sheet links are green. USD, gross published rates, no free-tier credits. | I2: Blue-font values are user-editable. Formula cells are black; cross-sheet links are green. USD, gross published rates, no free-tier credits. | J2: Blue-font values are user-editable. Formula cells are black; cross-sheet links are green. USD, gross published rates, no free-tier credits. | K2: Blue-font values are user-editable. Formula cells are black; cross-sheet links are green. USD, gross published rates, no free-tier credits.
A4: Average-case monthly workload | B4: Average-case monthly workload | C4: Average-case monthly workload | D4: Average-case monthly workload
A5: Driver | B5: Base value | C5: Unit | D5: Basis / note
A6: Analysis as of | B6: 46231 | C6: date | D6: Pricing and code review date
A7: Billing days per month | B7: 30 | C7: days | D7: Used for daily Vertex grounding allowance
A8: Companies processed | B8: 20 | C8: companies/month | D8: Average-case planning assumption
A9: Reports per company | B9: 12 | C9: reports/company | D9: Download and PageIndex volume
A10: Reports processed | B10: =B8*B9 -> 240 | C10: reports/month | D10: Companies × reports/company
A11: Questions per company | B11: 50 | C11: questions/company | D11: Question blocks answered by the ReAct loop
A12: Questions answered | B12: =B8*B11 -> 1000 | C12: questions/month | D12: Companies × questions/company
A13: Average PDF pages | B13: 150 | C13: pages/report | D13: Drives PageIndex token estimate
A14: Average PDF size | B14: 10 | C14: MB/report | D14: Drives incremental S3 storage
A15: Existing retained PDFs + indexes | B15: 50 | C15: GB | D15: Opening S3 footprint before this month
A16: S3 versioning multiplier | B16: 1.1 | C16: x | D16: Allows 10% overhead for prior object versions
A17: Total private ECR image storage | B17: 3 | C17: GB | D17: Four runtime/Lambda repositories combined
A18: Existing DynamoDB table size | B18: 0.1 | C18: GB | D18: Provenance table including item overhead
A21: Model usage assumptions by workload | B21: Model usage assumptions by workload | C21: Model usage assumptions by workload | D21: Model usage assumptions by workload | E21: Model usage assumptions by workload | F21: Model usage assumptions by workload | G21: Model usage assumptions by workload | H21: Model usage assumptions by workload | I21: Model usage assumptions by workload | J21: Model usage assumptions by workload | K21: Model usage assumptions by workload
A22: Agent | B22: Workload | C22: Model / service | D22: Driver | E22: Units / month | F22: Calls / unit | G22: Input tokens / call | H22: Output tokens / call | I22: Monthly input tokens | J22: Monthly output tokens | K22: Monthly calls
A23: Download Agent | B23: Query prep, class match, query generation | C23: Claude Sonnet 5 | D23: report | E23: =$B$10 -> 240 | F23: 3 | G23: 2000 | H23: 250 | I23: =E23*F23*G23 -> 1440000 | J23: =E23*F23*H23 -> 180000 | K23: =E23*F23 -> 720
A24: Download Agent | B24: Candidate verification / selection | C24: Claude Sonnet 5 | D24: report | E24: =$B$10 -> 240 | F24: 4 | G24: 5000 | H24: 150 | I24: =E24*F24*G24 -> 4800000 | J24: =E24*F24*H24 -> 144000 | K24: =E24*F24 -> 960
A25: Download Agent | B25: Grounded document discovery | C25: Gemini 2.5 Flash (thinking) | D25: report | E25: =$B$10 -> 240 | F25: 6 | G25: 800 | H25: 350 | I25: =E25*F25*G25 -> 1152000 | J25: =E25*F25*H25 -> 504000 | K25: =E25*F25 -> 1440
A26: Download Agent | B26: Company identity hint | C26: Gemini 2.5 Flash (thinking) | D26: company | E26: =$B$8 -> 20 | F26: 1 | G26: 600 | H26: 350 | I26: =E26*F26*G26 -> 12000 | J26: =E26*F26*H26 -> 7000 | K26: =E26*F26 -> 20
A27: Download Agent | B27: Browser-vision fallback | C27: Amazon Nova 2 Lite | D27: report | E27: =$B$10 -> 240 | F27: 0.05 | G27: 730 | H27: 100 | I27: =E27*F27*G27 -> 8760 | J27: =E27*F27*H27 -> 1200 | K27: =E27*F27 -> 12
A28: PageIndex Agent | B28: Hierarchical tree indexing | C28: Claude Sonnet 4.5 | D28: report | E28: =$B$10 -> 240 | F28: 1 | G28: =25000+$B$13*900 -> 160000 | H28: =2000+$B$13*90 -> 15500 | I28: =E28*F28*G28 -> 38400000 | J28: =E28*F28*H28 -> 3720000 | K28: =E28*F28 -> 240
A29: Answering Agent | B29: ReAct tool loop | C29: Claude Sonnet 5 | D29: question | E29: =$B$12 -> 1000 | F29: 6 | G29: 12000 | H29: 700 | I29: =E29*F29*G29 -> 72000000 | J29: =E29*F29*H29 -> 4200000 | K29: =E29*F29 -> 6000
A32: Infrastructure consumption assumptions | B32: Infrastructure consumption assumptions | C32: Infrastructure consumption assumptions | D32: Infrastructure consumption assumptions
A33: Driver | B33: Base value | C33: Unit | D33: Basis / note
A34: Download runtime active CPU | B34: 180 | C34: seconds/report | D34: CPU-active time; I/O waits do not accrue CPU
A35: Download runtime memory duration | B35: 480 | C35: seconds/report | D35: Average session memory duration
A36: Download runtime memory | B36: 1.5 | C36: GB | D36: Average working set
A37: Browser fallback rate | B37: 0.3 | C37: % of reports | D37: AgentCore Browser is a downstream fallback
A38: Browser active CPU | B38: 60 | C38: seconds/session | D38: 2 vCPU during active work
A39: Browser vCPU | B39: 2 | C39: vCPU | D39: Active browser allocation
A40: Browser session duration | B40: 240 | C40: seconds/session | D40: Memory billed through session duration
A41: Browser memory | B41: 4 | C41: GB | D41: Average browser working set
A42: PageIndex runtime active CPU | B42: 300 | C42: seconds/report | D42: 50% active CPU over a 10-minute job
A43: PageIndex runtime memory duration | B43: 600 | C43: seconds/report | D43: Average index job duration
A44: PageIndex runtime memory | B44: 2 | C44: GB | D44: PDF + index construction working set
A45: Answer runtime active CPU | B45: 30 | C45: seconds/question | D45: Excludes Bedrock/tool I/O waits
...

Sheet Model Cost
A1: Monthly Model & Vertex Cost | B1: Monthly Model & Vertex Cost | C1: Monthly Model & Vertex Cost | D1: Monthly Model & Vertex Cost | E1: Monthly Model & Vertex Cost | F1: Monthly Model & Vertex Cost | G1: Monthly Model & Vertex Cost | H1: Monthly Model & Vertex Cost | I1: Monthly Model & Vertex Cost | J1: Monthly Model & Vertex Cost | K1: Monthly Model & Vertex Cost | L1: Monthly Model & Vertex Cost | M1: Monthly Model & Vertex Cost
A2: Current pricing uses Claude Sonnet 5 launch pricing through 2026-08-31. Post-promo shows the recurring $3/$15 token rate. | B2: Current pricing uses Claude Sonnet 5 launch pricing through 2026-08-31. Post-promo shows the recurring $3/$15 token rate. | C2: Current pricing uses Claude Sonnet 5 launch pricing through 2026-08-31. Post-promo shows the recurring $3/$15 token rate. | D2: Current pricing uses Claude Sonnet 5 launch pricing through 2026-08-31. Post-promo shows the recurring $3/$15 token rate. | E2: Current pricing uses Claude Sonnet 5 launch pricing through 2026-08-31. Post-promo shows the recurring $3/$15 token rate. | F2: Current pricing uses Claude Sonnet 5 launch pricing through 2026-08-31. Post-promo shows the recurring $3/$15 token rate. | G2: Current pricing uses Claude Sonnet 5 launch pricing through 2026-08-31. Post-promo shows the recurring $3/$15 token rate. | H2: Current pricing uses Claude Sonnet 5 launch pricing through 2026-08-31. Post-promo shows the recurring $3/$15 token rate. | I2: Current pricing uses Claude Sonnet 5 launch pricing through 2026-08-31. Post-promo shows the recurring $3/$15 token rate. | J2: Current pricing uses Claude Sonnet 5 launch pricing through 2026-08-31. Post-promo shows the recurring $3/$15 token rate. | K2: Current pricing uses Claude Sonnet 5 launch pricing through 2026-08-31. Post-promo shows the recurring $3/$15 token rate. | L2: Current pricing uses Claude Sonnet 5 launch pricing through 2026-08-31. Post-promo shows the recurring $3/$15 token rate. | M2: Current pricing uses Claude Sonnet 5 launch pricing through 2026-08-31. Post-promo shows the recurring $3/$15 token rate.
A4: Published model rates (USD per 1M tokens) | B4: Published model rates (USD per 1M tokens) | C4: Published model rates (USD per 1M tokens) | D4: Published model rates (USD per 1M tokens) | E4: Published model rates (USD per 1M tokens) | F4: Published model rates (USD per 1M tokens) | H4: Vertex Google Search grounding | I4: Vertex Google Search grounding
A5: Model | B5: Input — current | C5: Output — current | D5: Input — post-promo | E5: Output — post-promo | F5: Pricing note | H5: Free grounded prompts | I5: 1500
A6: Claude Sonnet 5 | B6: 2 | C6: 10 | D6: 3 | E6: 15 | F6: AWS launch price ends 2026-08-31 | H6: Grounding price | I6: 35
A7: Claude Sonnet 4.5 | B7: 3 | C7: 15 | D7: 3 | E7: 15 | F7: AWS standard global / cross-region rate | H7: Allowance period | I7: per day
A8: Gemini 2.5 Flash (thinking) | B8: 0.15 | C8: 3.5 | D8: 0.15 | E8: 3.5 | F8: Thinking output rate because thinking is not disabled
A9: Amazon Nova 2 Lite | B9: 0.3 | C9: 2.5 | D9: 0.3 | E9: 2.5 | F9: Bedrock standard on-demand
A12: Monthly model cost calculation | B12: Monthly model cost calculation | C12: Monthly model cost calculation | D12: Monthly model cost calculation | E12: Monthly model cost calculation | F12: Monthly model cost calculation | G12: Monthly model cost calculation | H12: Monthly model cost calculation | I12: Monthly model cost calculation | J12: Monthly model cost calculation | K12: Monthly model cost calculation | L12: Monthly model cost calculation | M12: Monthly model cost calculation
A13: Agent | B13: Workload | C13: Model / service | D13: Monthly calls | E13: Input tokens | F13: Output tokens | G13: Input rate | H13: Output rate | I13: Input cost | J13: Output cost | K13: Grounding cost | L13: Current total | M13: Post-promo total
A14: Download Agent | B14: Query prep, class match, query generation | C14: Claude Sonnet 5 | D14: =Assumptions!K23 -> 720 | E14: =Assumptions!I23 -> 1440000 | F14: =Assumptions!J23 -> 180000 | G14: =$B$6 -> 2 | H14: =$C$6 -> 10 | I14: =E14/1000000*G14 -> 2.88 | J14: =F14/1000000*H14 -> 1.8 | K14: 0 | L14: =I14+J14+K14 -> 4.68 | M14: =E14/1000000*$D$6+F14/1000000*$E$6+K14 -> 7.02
A15: Download Agent | B15: Candidate verification / selection | C15: Claude Sonnet 5 | D15: =Assumptions!K24 -> 960 | E15: =Assumptions!I24 -> 4800000 | F15: =Assumptions!J24 -> 144000 | G15: =$B$6 -> 2 | H15: =$C$6 -> 10 | I15: =E15/1000000*G15 -> 9.6 | J15: =F15/1000000*H15 -> 1.44 | K15: 0 | L15: =I15+J15+K15 -> 11.04 | M15: =E15/1000000*$D$6+F15/1000000*$E$6+K15 -> 16.56
A16: Download Agent | B16: Grounded document discovery | C16: Gemini 2.5 Flash (thinking) | D16: =Assumptions!K25 -> 1440 | E16: =Assumptions!I25 -> 1152000 | F16: =Assumptions!J25 -> 504000 | G16: =$B$8 -> 0.15 | H16: =$C$8 -> 3.5 | I16: =E16/1000000*G16 -> 0.1728 | J16: =F16/1000000*H16 -> 1.764 | K16: 0 | L16: =I16+J16+K16 -> 1.9368 | M16: =E16/1000000*$D$8+F16/1000000*$E$8+K16 -> 1.9368
A17: Download Agent | B17: Company identity hint | C17: Gemini 2.5 Flash (thinking) | D17: =Assumptions!K26 -> 20 | E17: =Assumptions!I26 -> 12000 | F17: =Assumptions!J26 -> 7000 | G17: =$B$8 -> 0.15 | H17: =$C$8 -> 3.5 | I17: =E17/1000000*G17 -> 0.0018 | J17: =F17/1000000*H17 -> 0.0245 | K17: 0 | L17: =I17+J17+K17 -> 0.0263 | M17: =E17/1000000*$D$8+F17/1000000*$E$8+K17 -> 0.0263
A18: Download Agent | B18: Browser-vision fallback | C18: Amazon Nova 2 Lite | D18: =Assumptions!K27 -> 12 | E18: =Assumptions!I27 -> 8760 | F18: =Assumptions!J27 -> 1200 | G18: =$B$9 -> 0.3 | H18: =$C$9 -> 2.5 | I18: =E18/1000000*G18 -> 0.002628 | J18: =F18/1000000*H18 -> 0.003 | K18: 0 | L18: =I18+J18+K18 -> 0.005628 | M18: =E18/1000000*$D$9+F18/1000000*$E$9+K18 -> 0.005628
A19: PageIndex Agent | B19: Hierarchical tree indexing | C19: Claude Sonnet 4.5 | D19: =Assumptions!K28 -> 240 | E19: =Assumptions!I28 -> 38400000 | F19: =Assumptions!J28 -> 3720000 | G19: =$B$7 -> 3 | H19: =$C$7 -> 15 | I19: =E19/1000000*G19 -> 115.2 | J19: =F19/1000000*H19 -> 55.8 | K19: 0 | L19: =I19+J19+K19 -> 171 | M19: =E19/1000000*$D$7+F19/1000000*$E$7+K19 -> 171
A20: Answering Agent | B20: ReAct tool loop | C20: Claude Sonnet 5 | D20: =Assumptions!K29 -> 6000 | E20: =Assumptions!I29 -> 72000000 | F20: =Assumptions!J29 -> 4200000 | G20: =$B$6 -> 2 | H20: =$C$6 -> 10 | I20: =E20/1000000*G20 -> 144 | J20: =F20/1000000*H20 -> 42 | K20: 0 | L20: =I20+J20+K20 -> 186 | M20: =E20/1000000*$D$6+F20/1000000*$E$6+K20 -> 279
A21: Download Agent | B21: Google Search grounding add-on | C21: Vertex grounding | D21: =D16+D17 -> 1460 | E21: 0 | F21: 0 | G21: 0 | H21: 0 | I21: 0 | J21: 0 | K21: =MAX(0,D21/Assumptions!$B$7-$I$5)*Assumptions!$B$7*$I$6/1000 -> 0 | L21: =K21 -> 0 | M21: =L21 -> 0
A22: TOTAL | D22: =SUM(D14:D21) -> 10852 | E22: =SUM(E14:E21) -> 117812760 | F22: =SUM(F14:F21) -> 8756200 | I22: =SUM(I14:I21) -> 271.85723 | J22: =SUM(J14:J21) -> 102.8315 | K22: =SUM(K14:K21) -> 0 | L22: =SUM(L14:L21) -> 374.68873 | M22: =SUM(M14:M21) -> 475.54873

Sheet Infra Cost
A1: Monthly Infrastructure Cost — Separate from Model Spend | B1: Monthly Infrastructure Cost — Separate from Model Spend | C1: Monthly Infrastructure Cost — Separate from Model Spend | D1: Monthly Infrastructure Cost — Separate from Model Spend | E1: Monthly Infrastructure Cost — Separate from Model Spend | F1: Monthly Infrastructure Cost — Separate from Model Spend | G1: Monthly Infrastructure Cost — Separate from Model Spend | H1: Monthly Infrastructure Cost — Separate from Model Spend | I1: Monthly Infrastructure Cost — Separate from Model Spend
A2: Includes AgentCore Runtime/Browser, Vertex Lambda, fallback web search, S3, DynamoDB, ECR, Secrets Manager, CloudWatch, KMS, and small AWS→GCP egress. | B2: Includes AgentCore Runtime/Browser, Vertex Lambda, fallback web search, S3, DynamoDB, ECR, Secrets Manager, CloudWatch, KMS, and small AWS→GCP egress. | C2: Includes AgentCore Runtime/Browser, Vertex Lambda, fallback web search, S3, DynamoDB, ECR, Secrets Manager, CloudWatch, KMS, and small AWS→GCP egress. | D2: Includes AgentCore Runtime/Browser, Vertex Lambda, fallback web search, S3, DynamoDB, ECR, Secrets Manager, CloudWatch, KMS, and small AWS→GCP egress. | E2: Includes AgentCore Runtime/Browser, Vertex Lambda, fallback web search, S3, DynamoDB, ECR, Secrets Manager, CloudWatch, KMS, and small AWS→GCP egress. | F2: Includes AgentCore Runtime/Browser, Vertex Lambda, fallback web search, S3, DynamoDB, ECR, Secrets Manager, CloudWatch, KMS, and small AWS→GCP egress. | G2: Includes AgentCore Runtime/Browser, Vertex Lambda, fallback web search, S3, DynamoDB, ECR, Secrets Manager, CloudWatch, KMS, and small AWS→GCP egress. | H2: Includes AgentCore Runtime/Browser, Vertex Lambda, fallback web search, S3, DynamoDB, ECR, Secrets Manager, CloudWatch, KMS, and small AWS→GCP egress. | I2: Includes AgentCore Runtime/Browser, Vertex Lambda, fallback web search, S3, DynamoDB, ECR, Secrets Manager, CloudWatch, KMS, and small AWS→GCP egress.
A4: Published infrastructure rates | B4: Published infrastructure rates | C4: Published infrastructure rates | D4: Published infrastructure rates
A5: Service / meter | B5: Rate | C5: Billing unit | D5: Pricing basis
A6: AgentCore Runtime CPU | B6: 0.0895 | C6: vCPU-hour | D6: AWS AgentCore
A7: AgentCore Runtime memory | B7: 0.00945 | C7: GB-hour | D7: AWS AgentCore
A8: AgentCore Browser CPU | B8: 0.0895 | C8: vCPU-hour | D8: AWS AgentCore
A9: AgentCore Browser memory | B9: 0.00945 | C9: GB-hour | D9: AWS AgentCore
A10: Lambda ARM compute | B10: 1.33334e-05 | C10: GB-second | D10: AWS Lambda first ARM tier
A11: Lambda requests | B11: 0.2 | C11: 1M requests | D11: AWS Lambda
A12: AgentCore Web Search | B12: 7 | C12: 1K queries | D12: Vertex fallback only
A13: AgentCore Gateway invoke | B13: 0.005 | C13: 1K invokes | D13: Vertex fallback only
A14: S3 Standard storage | B14: 0.023 | C14: GB-month | D14: us-east-1
A15: S3 PUT/COPY/POST/LIST | B15: 0.005 | C15: 1K requests | D15: us-east-1
A16: S3 GET | B16: 0.0004 | C16: 1K requests | D16: us-east-1
A17: DynamoDB on-demand write | B17: 0.625 | C17: 1M WRU | D17: Standard table
... A26: Internet data transfer out | B26: 0.09 | C26: GB | D26: First paid tier; free allowance excluded
A28: Monthly infrastructure calculation | B28: Monthly infrastructure calculation | C28: Monthly infrastructure calculation | D28: Monthly infrastructure calculation | E28: Monthly infrastructure calculation | F28: Monthly infrastructure calculation | G28: Monthly infrastructure calculation | H28: Monthly infrastructure calculation | I28: Monthly infrastructure calculation
A29: Agent | B29: Service / meter | C29: Volume driver | D29: Monthly volume | E29: Usage per driver | F29: Billable usage | G29: Rate | H29: Monthly cost | I29: Notes
A30: Download Agent | B30: AgentCore Runtime CPU | C30: reports | D30: =Assumptions!$B$10 -> 240 | E30: =Assumptions!$B$34/3600 -> 0.05 | F30: =D30*E30 -> 12 | G30: =$B$6 -> 0.0895 | H30: =F30*G30 -> 1.074 | I30: 1 vCPU active
A31: Download Agent | B31: AgentCore Runtime memory | C31: reports | D31: =Assumptions!$B$10 -> 240 | E31: =Assumptions!$B$35*Assumptions!$B$36/3600 -> 0.2 | F31: =D31*E31 -> 48 | G31: =$B$7 -> 0.00945 | H31: =F31*G31 -> 0.4536 | I31: GB-hours
A32: Download Agent | B32: AgentCore Browser CPU | C32: reports | D32: =Assumptions!$B$10 -> 240 | E32: =Assumptions!$B$37*Assumptions!$B$38*Assumptions!$B$39/3600 -> 0.01 | F32: =D32*E32 -> 2.4 | G32: =$B$8 -> 0.0895 | H32: =F32*G32 -> 0.2148 | I32: 30% fallback × 2 vCPU
A33: Download Agent | B33: AgentCore Browser memory | C33: reports | D33: =Assumptions!$B$10 -> 240 | E33: =Assumptions!$B$37*Assumptions!$B$40*Assumptions!$B$41/3600 -> 0.08 | F33: =D33*E33 -> 19.2 | G33: =$B$9 -> 0.00945 | H33: =F33*G33 -> 0.18144 | I33: 30% fallback × 4 GB
A34: PageIndex Agent | B34: AgentCore Runtime CPU | C34: reports | D34: =Assumptions!$B$10 -> 240 | E34: =Assumptions!$B$42/3600 -> 0.083333333 | F34: =D34*E34 -> 20 | G34: =$B$6 -> 0.0895 | H34: =F34*G34 -> 1.79 | I34: 1 vCPU active
A35: PageIndex Agent | B35: AgentCore Runtime memory | C35: reports | D35: =Assumptions!$B$10 -> 240 | E35: =Assumptions!$B$43*Assumptions!$B$44/3600 -> 0.33333333 | F35: =D35*E35 -> 80 | G35: =$B$7 -> 0.00945 | H35: =F35*G35 -> 0.756 | I35: 2 GB working set
A36: Answering Agent | B36: AgentCore Runtime CPU | C36: questions | D36: =Assumptions!$B$12 -> 1000 | E36: =Assumptions!$B$45/3600 -> 0.0083333333 | F36: =D36*E36 -> 8.3333333 | G36: =$B$6 -> 0.0895 | H36: =F36*G36 -> 0.74583333 | I36: 1 vCPU active
A37: Answering Agent | B37: AgentCore Runtime memory | C37: questions | D37: =Assumptions!$B$12 -> 1000 | E37: =Assumptions!$B$46*Assumptions!$B$47/3600 -> 0.033333333 | F37: =D37*E37 -> 33.333333 | G37: =$B$7 -> 0.00945 | H37: =F37*G37 -> 0.315 | I37: 1 GB working set
A38: Download Agent | B38: Vertex Lambda ARM compute | C38: Vertex calls | D38: ='Model Cost'!$D$16+'Model Cost'!$D$17 -> 1460 | E38: =Assumptions!$B$48*Assumptions!$B$49 -> 2.5 | F38: =D38*E38 -> 3650 | G38: =$B$10 -> 1.33334e-05 | H38: =F38*G38 -> 0.04866691 | I38: 512 MB × 5 sec
A39: Download Agent | B39: Vertex Lambda requests | C39: Vertex calls | D39: ='Model Cost'!$D$16+'Model Cost'!$D$17 -> 1460 | E39: =1/1000000 -> 1e-06 | F39: =D39*E39 -> 0.00146 | G39: =$B$11 -> 0.2 | H39: =F39*G39 -> 0.000292 | I39: RequestResponse invokes
A40: Download Agent | B40: AgentCore Web Search fallback | C40: Vertex calls | D40: ='Model Cost'!$D$16+'Model Cost'!$D$17 -> 1460 | E40: =Assumptions!$B$50/1000 -> 5e-05 | F40: =D40*E40 -> 0.073 | G40: =$B$12 -> 7 | H40: =F40*G40 -> 0.511 | I40: 5% fallback
A41: Download Agent | B41: AgentCore Gateway invokes | C41: Vertex calls | D41: ='Model Cost'!$D$16+'Model Cost'!$D$17 -> 1460 | E41: =Assumptions!$B$50/1000 -> 5e-05 | F41: =D41*E41 -> 0.073 | G41: =$B$13 -> 0.005 | H41: =F41*G41 -> 0.000365 | I41: 5% fallback
A42: Shared | B42: S3 Standard storage | C42: opening + half-month new | D42: 1 | E42: =(Assumptions!$B$15+Assumptions!$B$10*Assumptions!$B$14/1024/2)*Assumptions!$B$16 -> 56.289063 | F42: =D42*E42 -> 56.289063 | G42: =$B$14 -> 0.023 | H42: =F42*G42 -> 1.2946484 | I42: Includes 10% versioning overhead
A43: Shared | B43: S3 PUT/LIST requests | C43: reports | D43: =Assumptions!$B$10 -> 240 | E43: =2/1000 -> 0.002 | F43: =D43*E43 -> 0.48 | G43: =$B$15 -> 0.005 | H43: =F43*G43 -> 0.0024 | I43: Download + incremental index writes
A44: Shared | B44: S3 GET requests | C44: reports + questions | D44: 1 | E44: =(Assumptions!$B$10*6+Assumptions!$B$12*0.2)/1000 -> 1.64 | F44: =D44*E44 -> 1.64 | G44: =$B$16 -> 0.0004 | H44: =F44*G44 -> 0.000656 | I44: 6/report + 0.2/question
A45: Download Agent | B45: DynamoDB writes | C45: reports | D45: =Assumptions!$B$10 -> 240 | E45: =1/1000000 -> 1e-06 | F45: =D45*E45 -> 0.00024 | G45: =$B$17 -> 0.625 | H45: =F45*G45 -> 0.00015 | I45: One provenance write/report
A46: Download Agent | B46: DynamoDB reads | C46: reports | D46: =Assumptions!$B$10 -> 240 | E46: =2/1000000 -> 2e-06 | F46: =D46*E46 -> 0.00048 | G46: =$B$18 -> 0.125 | H46: =F46*G46 -> 6e-05 | I46: Two reads/report
A47: Download Agent | B47: DynamoDB storage | C47: existing table | D47: 1 | E47: =Assumptions!$B$18 -> 0.1 | F47: =D47*E47 -> 0.1 | G47: =$B$19 -> 0.25 | H47: =F47*G47 -> 0.025 | I47: Standard table
A48: Download Agent | B48: DynamoDB PITR | C48: existing table | D48: 1 | E48: =Assumptions!$B$18 -> 0.1 | F48: =D48*E48 -> 0.1 | G48: =$B$20 -> 0.2 | H48: =F48*G48 -> 0.02 | I48: Continuous backup
A49: Shared | B49: ECR private storage | C49: stored images | D49: 1 | E49: =Assumptions!$B$17 -> 3 | F49: =D49*E49 -> 3 | G49: =$B$21 -> 0.1 | H49: =F49*G49 -> 0.3 | I49: Four repositories combined
A50: Download Agent | B50: Secrets Manager | C50: WIF secret | D50: 1 | E50: 1 | F50: 1 | G50: =$B$22 -> 0.4 | H50: =F50*G50 -> 0.4 | I50: One secret-month
...

Sheet Sensitivity
A1: Low / Base / High Monthly Sensitivity | B1: Low / Base / High Monthly Sensitivity | C1: Low / Base / High Monthly Sensitivity | D1: Low / Base / High Monthly Sensitivity | E1: Low / Base / High Monthly Sensitivity | F1: Low / Base / High Monthly Sensitivity | G1: Low / Base / High Monthly Sensitivity | H1: Low / Base / High Monthly Sensitivity | I1: Low / Base / High Monthly Sensitivity | J1: Low / Base / High Monthly Sensitivity
A2: Scenarios flex workload and document length. Current Sonnet 5 promotional pricing is used; fixed shared infrastructure remains unchanged. | B2: Scenarios flex workload and document length. Current Sonnet 5 promotional pricing is used; fixed shared infrastructure remains unchanged. | C2: Scenarios flex workload and document length. Current Sonnet 5 promotional pricing is used; fixed shared infrastructure remains unchanged. | D2: Scenarios flex workload and document length. Current Sonnet 5 promotional pricing is used; fixed shared infrastructure remains unchanged. | E2: Scenarios flex workload and document length. Current Sonnet 5 promotional pricing is used; fixed shared infrastructure remains unchanged. | F2: Scenarios flex workload and document length. Current Sonnet 5 promotional pricing is used; fixed shared infrastructure remains unchanged. | G2: Scenarios flex workload and document length. Current Sonnet 5 promotional pricing is used; fixed shared infrastructure remains unchanged. | H2: Scenarios flex workload and document length. Current Sonnet 5 promotional pricing is used; fixed shared infrastructure remains unchanged. | I2: Scenarios flex workload and document length. Current Sonnet 5 promotional pricing is used; fixed shared infrastructure remains unchanged. | J2: Scenarios flex workload and document length. Current Sonnet 5 promotional pricing is used; fixed shared infrastructure remains unchanged.
A4: Scenario analysis | B4: Scenario analysis | C4: Scenario analysis | D4: Scenario analysis | E4: Scenario analysis | F4: Scenario analysis | G4: Scenario analysis | H4: Scenario analysis | I4: Scenario analysis | J4: Scenario analysis
A5: Scenario | B5: Companies / month | C5: Reports / company | D5: Questions / company | E5: Avg pages / report | F5: Reports / month | G5: Questions / month | H5: Model cost | I5: Infrastructure | J5: All-in cost
A6: Low | B6: 10 | C6: 8 | D6: 25 | E6: 80 | F6: =B6*C6 -> 80 | G6: =B6*D6 -> 250 | H6: =(('Model Cost'!$L$14+'Model Cost'!$L$15+'Model Cost'!$L$16+'Model Cost'!$L$18)/Assumptions!$B$10)*F6+('Model Cost'!$L$17/Assumptions!$B$8)*B6+F6*((25000+E6*900)*'Model Cost'!$B$7/1000000+(2000+E6*90)*'Model Cost'!$C$7/1000000)+('Model Cost'!$L$20/Assumptions!$B$12)*G6 -> 86.720626 | I6: =(SUMIF('Infra Cost'!$A$30:$A$56,"Download Agent",'Infra Cost'!$H$30:$H$56)/Assumptions!$B$10)*F6+(SUMIF('Infra Cost'!$A$30:$A$56,"PageIndex Agent",'Infra Cost'!$H$30:$H$56)/Assumptions!$B$10)*F6+(SUMIF('Infra Cost'!$A$30:$A$56,"Answering Agent",'Infra Cost'!$H$30:$H$56)/Assumptions!$B$12)*G6+SUMIF('Infra Cost'!$A$30:$A$56,"Shared",'Infra Cost'!$H$30:$H$56) -> 4.2700156 | J6: =H6+I6 -> 90.990642
A7: Base | B7: =Assumptions!$B$8 -> 20 | C7: =Assumptions!$B$9 -> 12 | D7: =Assumptions!$B$11 -> 50 | E7: =Assumptions!$B$13 -> 150 | F7: =B7*C7 -> 240 | G7: =B7*D7 -> 1000 | H7: =(('Model Cost'!$L$14+'Model Cost'!$L$15+'Model Cost'!$L$16+'Model Cost'!$L$18)/Assumptions!$B$10)*F7+('Model Cost'!$L$17/Assumptions!$B$8)*B7+F7*((25000+E7*900)*'Model Cost'!$B$7/1000000+(2000+E7*90)*'Model Cost'!$C$7/1000000)+('Model Cost'!$L$20/Assumptions!$B$12)*G7 -> 374.68873 | I7: =(SUMIF('Infra Cost'!$A$30:$A$56,"Download Agent",'Infra Cost'!$H$30:$H$56)/Assumptions!$B$10)*F7+(SUMIF('Infra Cost'!$A$30:$A$56,"PageIndex Agent",'Infra Cost'!$H$30:$H$56)/Assumptions!$B$10)*F7+(SUMIF('Infra Cost'!$A$30:$A$56,"Answering Agent",'Infra Cost'!$H$30:$H$56)/Assumptions!$B$12)*G7+SUMIF('Infra Cost'!$A$30:$A$56,"Shared",'Infra Cost'!$H$30:$H$56) -> 9.5808814 | J7: =H7+I7 -> 384.26961
A8: High | B8: 50 | C8: 15 | D8: 100 | E8: 250 | F8: =B8*C8 -> 750 | G8: =B8*D8 -> 5000 | H8: =(('Model Cost'!$L$14+'Model Cost'!$L$15+'Model Cost'!$L$16+'Model Cost'!$L$18)/Assumptions!$B$10)*F8+('Model Cost'!$L$17/Assumptions!$B$8)*B8+F8*((25000+E8*900)*'Model Cost'!$B$7/1000000+(2000+E8*90)*'Model Cost'!$C$7/1000000)+('Model Cost'!$L$20/Assumptions!$B$12)*G8 -> 1823.3858 | I8: =(SUMIF('Infra Cost'!$A$30:$A$56,"Download Agent",'Infra Cost'!$H$30:$H$56)/Assumptions!$B$10)*F8+(SUMIF('Infra Cost'!$A$30:$A$56,"PageIndex Agent",'Infra Cost'!$H$30:$H$56)/Assumptions!$B$10)*F8+(SUMIF('Infra Cost'!$A$30:$A$56,"Answering Agent",'Infra Cost'!$H$30:$H$56)/Assumptions!$B$12)*G8+SUMIF('Infra Cost'!$A$30:$A$56,"Shared",'Infra Cost'!$H$30:$H$56) -> 28.609459 | J8: =H8+I8 -> 1851.9953
A11: Sensitivity caveat: model cost is proportional to the configured per-call token assumptions except PageIndex, which recalculates a fixed token block plus a per-page token component. Infrastructure scales variable AgentCore/Lambda/log costs by reports or questions; shared storage/ECR/Secrets/retained logs are held fixed. Vertex grounding remains within the daily free allowance for all three scenarios when work is evenly distributed. | B11: Sensitivity caveat: model cost is proportional to the configured per-call token assumptions except PageIndex, which recalculates a fixed token block plus a per-page token component. Infrastructure scales variable AgentCore/Lambda/log costs by reports or questions; shared storage/ECR/Secrets/retained logs are held fixed. Vertex grounding remains within the daily free allowance for all three scenarios when work is evenly distributed. | C11: Sensitivity caveat: model cost is proportional to the configured per-call token assumptions except PageIndex, which recalculates a fixed token block plus a per-page token component. Infrastructure scales variable AgentCore/Lambda/log costs by reports or questions; shared storage/ECR/Secrets/retained logs are held fixed. Vertex grounding remains within the daily free allowance for all three scenarios when work is evenly distributed. | D11: Sensitivity caveat: model cost is proportional to the configured per-call token assumptions except PageIndex, which recalculates a fixed token block plus a per-page token component. Infrastructure scales variable AgentCore/Lambda/log costs by reports or questions; shared storage/ECR/Secrets/retained logs are held fixed. Vertex grounding remains within the daily free allowance for all three scenarios when work is evenly distributed. | E11: Sensitivity caveat: model cost is proportional to the configured per-call token assumptions except PageIndex, which recalculates a fixed token block plus a per-page token component. Infrastructure scales variable AgentCore/Lambda/log costs by reports or questions; shared storage/ECR/Secrets/retained logs are held fixed. Vertex grounding remains within the daily free allowance for all three scenarios when work is evenly distributed. | F11: Sensitivity caveat: model cost is proportional to the configured per-call token assumptions except PageIndex, which recalculates a fixed token block plus a per-page token component. Infrastructure scales variable AgentCore/Lambda/log costs by reports or questions; shared storage/ECR/Secrets/retained logs are held fixed. Vertex grounding remains within the daily free allowance for all three scenarios when work is evenly distributed. | G11: Sensitivity caveat: model cost is proportional to the configured per-call token assumptions except PageIndex, which recalculates a fixed token block plus a per-page token component. Infrastructure scales variable AgentCore/Lambda/log costs by reports or questions; shared storage/ECR/Secrets/retained logs are held fixed. Vertex grounding remains within the daily free allowance for all three scenarios when work is evenly distributed. | H11: Sensitivity caveat: model cost is proportional to the configured per-call token assumptions except PageIndex, which recalculates a fixed token block plus a per-page token component. Infrastructure scales variable AgentCore/Lambda/log costs by reports or questions; shared storage/ECR/Secrets/retained logs are held fixed. Vertex grounding remains within the daily free allowance for all three scenarios when work is evenly distributed. | I11: Sensitivity caveat: model cost is proportional to the configured per-call token assumptions except PageIndex, which recalculates a fixed token block plus a per-page token component. Infrastructure scales variable AgentCore/Lambda/log costs by reports or questions; shared storage/ECR/Secrets/retained logs are held fixed. Vertex grounding remains within the daily free allowance for all three scenarios when work is evenly distributed. | J11: Sensitivity caveat: model cost is proportional to the configured per-call token assumptions except PageIndex, which recalculates a fixed token block plus a per-page token component. Infrastructure scales variable AgentCore/Lambda/log costs by reports or questions; shared storage/ECR/Secrets/retained logs are held fixed. Vertex grounding remains within the daily free allowance for all three scenarios when work is evenly distributed.
A12: Sensitivity caveat: model cost is proportional to the configured per-call token assumptions except PageIndex, which recalculates a fixed token block plus a per-page token component. Infrastructure scales variable AgentCore/Lambda/log costs by reports or questions; shared storage/ECR/Secrets/retained logs are held fixed. Vertex grounding remains within the daily free allowance for all three scenarios when work is evenly distributed. | B12: Sensitivity caveat: model cost is proportional to the configured per-call token assumptions except PageIndex, which recalculates a fixed token block plus a per-page token component. Infrastructure scales variable AgentCore/Lambda/log costs by reports or questions; shared storage/ECR/Secrets/retained logs are held fixed. Vertex grounding remains within the daily free allowance for all three scenarios when work is evenly distributed. | C12: Sensitivity caveat: model cost is proportional to the configured per-call token assumptions except PageIndex, which recalculates a fixed token block plus a per-page token component. Infrastructure scales variable AgentCore/Lambda/log costs by reports or questions; shared storage/ECR/Secrets/retained logs are held fixed. Vertex grounding remains within the daily free allowance for all three scenarios when work is evenly distributed. | D12: Sensitivity caveat: model cost is proportional to the configured per-call token assumptions except PageIndex, which recalculates a fixed token block plus a per-page token component. Infrastructure scales variable AgentCore/Lambda/log costs by reports or questions; shared storage/ECR/Secrets/retained logs are held fixed. Vertex grounding remains within the daily free allowance for all three scenarios when work is evenly distributed. | E12: Sensitivity caveat: model cost is proportional to the configured per-call token assumptions except PageIndex, which recalculates a fixed token block plus a per-page token component. Infrastructure scales variable AgentCore/Lambda/log costs by reports or questions; shared storage/ECR/Secrets/retained logs are held fixed. Vertex grounding remains within the daily free allowance for all three scenarios when work is evenly distributed. | F12: Sensitivity caveat: model cost is proportional to the configured per-call token assumptions except PageIndex, which recalculates a fixed token block plus a per-page token component. Infrastructure scales variable AgentCore/Lambda/log costs by reports or questions; shared storage/ECR/Secrets/retained logs are held fixed. Vertex grounding remains within the daily free allowance for all three scenarios when work is evenly distributed. | G12: Sensitivity caveat: model cost is proportional to the configured per-call token assumptions except PageIndex, which recalculates a fixed token block plus a per-page token component. Infrastructure scales variable AgentCore/Lambda/log costs by reports or questions; shared storage/ECR/Secrets/retained logs are held fixed. Vertex grounding remains within the daily free allowance for all three scenarios when work is evenly distributed. | H12: Sensitivity caveat: model cost is proportional to the configured per-call token assumptions except PageIndex, which recalculates a fixed token block plus a per-page token component. Infrastructure scales variable AgentCore/Lambda/log costs by reports or questions; shared storage/ECR/Secrets/retained logs are held fixed. Vertex grounding remains within the daily free allowance for all three scenarios when work is evenly distributed. | I12: Sensitivity caveat: model cost is proportional to the configured per-call token assumptions except PageIndex, which recalculates a fixed token block plus a per-page token component. Infrastructure scales variable AgentCore/Lambda/log costs by reports or questions; shared storage/ECR/Secrets/retained logs are held fixed. Vertex grounding remains within the daily free allowance for all three scenarios when work is evenly distributed. | J12: Sensitivity caveat: model cost is proportional to the configured per-call token assumptions except PageIndex, which recalculates a fixed token block plus a per-page token component. Infrastructure scales variable AgentCore/Lambda/log costs by reports or questions; shared storage/ECR/Secrets/retained logs are held fixed. Vertex grounding remains within the daily free allowance for all three scenarios when work is evenly distributed.
A13: Sensitivity caveat: model cost is proportional to the configured per-call token assumptions except PageIndex, which recalculates a fixed token block plus a per-page token component. Infrastructure scales variable AgentCore/Lambda/log costs by reports or questions; shared storage/ECR/Secrets/retained logs are held fixed. Vertex grounding remains within the daily free allowance for all three scenarios when work is evenly distributed. | B13: Sensitivity caveat: model cost is proportional to the configured per-call token assumptions except PageIndex, which recalculates a fixed token block plus a per-page token component. Infrastructure scales variable AgentCore/Lambda/log costs by reports or questions; shared storage/ECR/Secrets/retained logs are held fixed. Vertex grounding remains within the daily free allowance for all three scenarios when work is evenly distributed. | C13: Sensitivity caveat: model cost is proportional to the configured per-call token assumptions except PageIndex, which recalculates a fixed token block plus a per-page token component. Infrastructure scales variable AgentCore/Lambda/log costs by reports or questions; shared storage/ECR/Secrets/retained logs are held fixed. Vertex grounding remains within the daily free allowance for all three scenarios when work is evenly distributed. | D13: Sensitivity caveat: model cost is proportional to the configured per-call token assumptions except PageIndex, which recalculates a fixed token block plus a per-page token component. Infrastructure scales variable AgentCore/Lambda/log costs by reports or questions; shared storage/ECR/Secrets/retained logs are held fixed. Vertex grounding remains within the daily free allowance for all three scenarios when work is evenly distributed. | E13: Sensitivity caveat: model cost is proportional to the configured per-call token assumptions except PageIndex, which recalculates a fixed token block plus a per-page token component. Infrastructure scales variable AgentCore/Lambda/log costs by reports or questions; shared storage/ECR/Secrets/retained logs are held fixed. Vertex grounding remains within the daily free allowance for all three scenarios when work is evenly distributed. | F13: Sensitivity caveat: model cost is proportional to the configured per-call token assumptions except PageIndex, which recalculates a fixed token block plus a per-page token component. Infrastructure scales variable AgentCore/Lambda/log costs by reports or questions; shared storage/ECR/Secrets/retained logs are held fixed. Vertex grounding remains within the daily free allowance for all three scenarios when work is evenly distributed. | G13: Sensitivity caveat: model cost is proportional to the configured per-call token assumptions except PageIndex, which recalculates a fixed token block plus a per-page token component. Infrastructure scales variable AgentCore/Lambda/log costs by reports or questions; shared storage/ECR/Secrets/retained logs are held fixed. Vertex grounding remains within the daily free allowance for all three scenarios when work is evenly distributed. | H13: Sensitivity caveat: model cost is proportional to the configured per-call token assumptions except PageIndex, which recalculates a fixed token block plus a per-page token component. Infrastructure scales variable AgentCore/Lambda/log costs by reports or questions; shared storage/ECR/Secrets/retained logs are held fixed. Vertex grounding remains within the daily free allowance for all three scenarios when work is evenly distributed. | I13: Sensitivity caveat: model cost is proportional to the configured per-call token assumptions except PageIndex, which recalculates a fixed token block plus a per-page token component. Infrastructure scales variable AgentCore/Lambda/log costs by reports or questions; shared storage/ECR/Secrets/retained logs are held fixed. Vertex grounding remains within the daily free allowance for all three scenarios when work is evenly distributed. | J13: Sensitivity caveat: model cost is proportional to the configured per-call token assumptions except PageIndex, which recalculates a fixed token block plus a per-page token component. Infrastructure scales variable AgentCore/Lambda/log costs by reports or questions; shared storage/ECR/Secrets/retained logs are held fixed. Vertex grounding remains within the daily free allowance for all three scenarios when work is evenly distributed.
A14: Sensitivity caveat: model cost is proportional to the configured per-call token assumptions except PageIndex, which recalculates a fixed token block plus a per-page token component. Infrastructure scales variable AgentCore/Lambda/log costs by reports or questions; shared storage/ECR/Secrets/retained logs are held fixed. Vertex grounding remains within the daily free allowance for all three scenarios when work is evenly distributed. | B14: Sensitivity caveat: model cost is proportional to the configured per-call token assumptions except PageIndex, which recalculates a fixed token block plus a per-page token component. Infrastructure scales variable AgentCore/Lambda/log costs by reports or questions; shared storage/ECR/Secrets/retained logs are held fixed. Vertex grounding remains within the daily free allowance for all three scenarios when work is evenly distributed. | C14: Sensitivity caveat: model cost is proportional to the configured per-call token assumptions except PageIndex, which recalculates a fixed token block plus a per-page token component. Infrastructure scales variable AgentCore/Lambda/log costs by reports or questions; shared storage/ECR/Secrets/retained logs are held fixed. Vertex grounding remains within the daily free allowance for all three scenarios when work is evenly distributed. | D14: Sensitivity caveat: model cost is proportional to the configured per-call token assumptions except PageIndex, which recalculates a fixed token block plus a per-page token component. Infrastructure scales variable AgentCore/Lambda/log costs by reports or questions; shared storage/ECR/Secrets/retained logs are held fixed. Vertex grounding remains within the daily free allowance for all three scenarios when work is evenly distributed. | E14: Sensitivity caveat: model cost is proportional to the configured per-call token assumptions except PageIndex, which recalculates a fixed token block plus a per-page token component. Infrastructure scales variable AgentCore/Lambda/log costs by reports or questions; shared storage/ECR/Secrets/retained logs are held fixed. Vertex grounding remains within the daily free allowance for all three scenarios when work is evenly distributed. | F14: Sensitivity caveat: model cost is proportional to the configured per-call token assumptions except PageIndex, which recalculates a fixed token block plus a per-page token component. Infrastructure scales variable AgentCore/Lambda/log costs by reports or questions; shared storage/ECR/Secrets/retained logs are held fixed. Vertex grounding remains within the daily free allowance for all three scenarios when work is evenly distributed. | G14: Sensitivity caveat: model cost is proportional to the configured per-call token assumptions except PageIndex, which recalculates a fixed token block plus a per-page token component. Infrastructure scales variable AgentCore/Lambda/log costs by reports or questions; shared storage/ECR/Secrets/retained logs are held fixed. Vertex grounding remains within the daily free allowance for all three scenarios when work is evenly distributed. | H14: Sensitivity caveat: model cost is proportional to the configured per-call token assumptions except PageIndex, which recalculates a fixed token block plus a per-page token component. Infrastructure scales variable AgentCore/Lambda/log costs by reports or questions; shared storage/ECR/Secrets/retained logs are held fixed. Vertex grounding remains within the daily free allowance for all three scenarios when work is evenly distributed. | I14: Sensitivity caveat: model cost is proportional to the configured per-call token assumptions except PageIndex, which recalculates a fixed token block plus a per-page token component. Infrastructure scales variable AgentCore/Lambda/log costs by reports or questions; shared storage/ECR/Secrets/retained logs are held fixed. Vertex grounding remains within the daily free allowance for all three scenarios when work is evenly distributed. | J14: Sensitivity caveat: model cost is proportional to the configured per-call token assumptions except PageIndex, which recalculates a fixed token block plus a per-page token component. Infrastructure scales variable AgentCore/Lambda/log costs by reports or questions; shared storage/ECR/Secrets/retained logs are held fixed. Vertex grounding remains within the daily free allowance for all three scenarios when work is evenly distributed.
A15: Sensitivity caveat: model cost is proportional to the configured per-call token assumptions except PageIndex, which recalculates a fixed token block plus a per-page token component. Infrastructure scales variable AgentCore/Lambda/log costs by reports or questions; shared storage/ECR/Secrets/retained logs are held fixed. Vertex grounding remains within the daily free allowance for all three scenarios when work is evenly distributed. | B15: Sensitivity caveat: model cost is proportional to the configured per-call token assumptions except PageIndex, which recalculates a fixed token block plus a per-page token component. Infrastructure scales variable AgentCore/Lambda/log costs by reports or questions; shared storage/ECR/Secrets/retained logs are held fixed. Vertex grounding remains within the daily free allowance for all three scenarios when work is evenly distributed. | C15: Sensitivity caveat: model cost is proportional to the configured per-call token assumptions except PageIndex, which recalculates a fixed token block plus a per-page token component. Infrastructure scales variable AgentCore/Lambda/log costs by reports or questions; shared storage/ECR/Secrets/retained logs are held fixed. Vertex grounding remains within the daily free allowance for all three scenarios when work is evenly distributed. | D15: Sensitivity caveat: model cost is proportional to the configured per-call token assumptions except PageIndex, which recalculates a fixed token block plus a per-page token component. Infrastructure scales variable AgentCore/Lambda/log costs by reports or questions; shared storage/ECR/Secrets/retained logs are held fixed. Vertex grounding remains within the daily free allowance for all three scenarios when work is evenly distributed. | E15: Sensitivity caveat: model cost is proportional to the configured per-call token assumptions except PageIndex, which recalculates a fixed token block plus a per-page token component. Infrastructure scales variable AgentCore/Lambda/log costs by reports or questions; shared storage/ECR/Secrets/retained logs are held fixed. Vertex grounding remains within the daily free allowance for all three scenarios when work is evenly distributed. | F15: Sensitivity caveat: model cost is proportional to the configured per-call token assumptions except PageIndex, which recalculates a fixed token block plus a per-page token component. Infrastructure scales variable AgentCore/Lambda/log costs by reports or questions; shared storage/ECR/Secrets/retained logs are held fixed. Vertex grounding remains within the daily free allowance for all three scenarios when work is evenly distributed. | G15: Sensitivity caveat: model cost is proportional to the configured per-call token assumptions except PageIndex, which recalculates a fixed token block plus a per-page token component. Infrastructure scales variable AgentCore/Lambda/log costs by reports or questions; shared storage/ECR/Secrets/retained logs are held fixed. Vertex grounding remains within the daily free allowance for all three scenarios when work is evenly distributed. | H15: Sensitivity caveat: model cost is proportional to the configured per-call token assumptions except PageIndex, which recalculates a fixed token block plus a per-page token component. Infrastructure scales variable AgentCore/Lambda/log costs by reports or questions; shared storage/ECR/Secrets/retained logs are held fixed. Vertex grounding remains within the daily free allowance for all three scenarios when work is evenly distributed. | I15: Sensitivity caveat: model cost is proportional to the configured per-call token assumptions except PageIndex, which recalculates a fixed token block plus a per-page token component. Infrastructure scales variable AgentCore/Lambda/log costs by reports or questions; shared storage/ECR/Secrets/retained logs are held fixed. Vertex grounding remains within the daily free allowance for all three scenarios when work is evenly distributed. | J15: Sensitivity caveat: model cost is proportional to the configured per-call token assumptions except PageIndex, which recalculates a fixed token block plus a per-page token component. Infrastructure scales variable AgentCore/Lambda/log costs by reports or questions; shared storage/ECR/Secrets/retained logs are held fixed. Vertex grounding remains within the daily free allowance for all three scenarios when work is evenly distributed.

Sheet Scenario Comparison
A1: Requested Workloads — Token & Monthly Cost Comparison | B1: Requested Workloads — Token & Monthly Cost Comparison | C1: Requested Workloads — Token & Monthly Cost Comparison | D1: Requested Workloads — Token & Monthly Cost Comparison | E1: Requested Workloads — Token & Monthly Cost Comparison | F1: Requested Workloads — Token & Monthly Cost Comparison | G1: Requested Workloads — Token & Monthly Cost Comparison | H1: Requested Workloads — Token & Monthly Cost Comparison | I1: Requested Workloads — Token & Monthly Cost Comparison | J1: Requested Workloads — Token & Monthly Cost Comparison | K1: Requested Workloads — Token & Monthly Cost Comparison
A2: Compares one company with 23 reports and 29 questions against the monthly portfolio of 20 companies, 240 reports, and 1,000 questions. Average document length remains 150 pages. | B2: Compares one company with 23 reports and 29 questions against the monthly portfolio of 20 companies, 240 reports, and 1,000 questions. Average document length remains 150 pages. | C2: Compares one company with 23 reports and 29 questions against the monthly portfolio of 20 companies, 240 reports, and 1,000 questions. Average document length remains 150 pages. | D2: Compares one company with 23 reports and 29 questions against the monthly portfolio of 20 companies, 240 reports, and 1,000 questions. Average document length remains 150 pages. | E2: Compares one company with 23 reports and 29 questions against the monthly portfolio of 20 companies, 240 reports, and 1,000 questions. Average document length remains 150 pages. | F2: Compares one company with 23 reports and 29 questions against the monthly portfolio of 20 companies, 240 reports, and 1,000 questions. Average document length remains 150 pages. | G2: Compares one company with 23 reports and 29 questions against the monthly portfolio of 20 companies, 240 reports, and 1,000 questions. Average document length remains 150 pages. | H2: Compares one company with 23 reports and 29 questions against the monthly portfolio of 20 companies, 240 reports, and 1,000 questions. Average document length remains 150 pages. | I2: Compares one company with 23 reports and 29 questions against the monthly portfolio of 20 companies, 240 reports, and 1,000 questions. Average document length remains 150 pages. | J2: Compares one company with 23 reports and 29 questions against the monthly portfolio of 20 companies, 240 reports, and 1,000 questions. Average document length remains 150 pages. | K2: Compares one company with 23 reports and 29 questions against the monthly portfolio of 20 companies, 240 reports, and 1,000 questions. Average document length remains 150 pages.
A4: Scenario summary | B4: Scenario summary | C4: Scenario summary | D4: Scenario summary | E4: Scenario summary | F4: Scenario summary | G4: Scenario summary | H4: Scenario summary | I4: Scenario summary | J4: Scenario summary | K4: Scenario summary
A5: Scenario | B5: Companies | C5: Reports | D5: Questions | E5: Avg pages / report | F5: Input tokens | G5: Output tokens | H5: Model cost — current | I5: Infrastructure | J5: All-in — current | K5: All-in — post-promo
A6: 1 company workload | B6: 1 | C6: 23 | D6: 29 | E6: =Assumptions!$B$13 -> 150 | F6: =C17 -> 6477839.5 | G6: =D17 -> 558115 | H6: =F17 -> 23.475464 | I6: =F28 -> 2.8188126 | J6: =H6+I6 -> 26.294277 | K6: =G17+I6 -> 29.744527
A7: Monthly portfolio | B7: 20 | C7: 240 | D7: 1000 | E7: =Assumptions!$B$13 -> 150 | F7: =C23 -> 117812760 | G7: =D23 -> 8756200 | H7: =F23 -> 374.68873 | I7: =F29 -> 9.5808814 | J7: =H7+I7 -> 384.26961 | K7: =G23+I7 -> 485.12961
A10: Model-wise token spend and cost | B10: Model-wise token spend and cost | C10: Model-wise token spend and cost | D10: Model-wise token spend and cost | E10: Model-wise token spend and cost | F10: Model-wise token spend and cost | G10: Model-wise token spend and cost | H10: Model-wise token spend and cost
A11: Scenario | B11: Model / service | C11: Input tokens | D11: Output tokens | E11: Total tokens | F11: Current cost | G11: Post-promo cost | H11: Calculation basis
